[2025-01-10T04:24:09.402+0000] {local_task_job_runner.py:123} INFO - ::group::Pre task execution logs
[2025-01-10T04:24:09.503+0000] {taskinstance.py:2613} INFO - Dependencies all met for dep_context=non-requeueable deps ti=<TaskInstance: data_processing.data_transform manual__2025-01-10T04:23:33.801988+00:00 [queued]>
[2025-01-10T04:24:09.506+0000] {taskinstance.py:2613} INFO - Dependencies all met for dep_context=requeueable deps ti=<TaskInstance: data_processing.data_transform manual__2025-01-10T04:23:33.801988+00:00 [queued]>
[2025-01-10T04:24:09.506+0000] {taskinstance.py:2866} INFO - Starting attempt 1 of 1
[2025-01-10T04:24:09.514+0000] {taskinstance.py:2889} INFO - Executing <Task(DockerOperator): data_transform> on 2025-01-10 04:23:33.801988+00:00
[2025-01-10T04:24:09.539+0000] {standard_task_runner.py:72} INFO - Started process 23659 to run task
[2025-01-10T04:24:09.543+0000] {standard_task_runner.py:104} INFO - Running: ['airflow', 'tasks', 'run', 'data_processing', 'data_transform', 'manual__2025-01-10T04:23:33.801988+00:00', '--job-id', '47', '--raw', '--subdir', 'DAGS_FOLDER/job_market_dag.py', '--cfg-path', '/tmp/tmpdfi_exdw']
[2025-01-10T04:24:09.544+0000] {standard_task_runner.py:105} INFO - Job 47: Subtask data_transform
[2025-01-10T04:24:09.577+0000] {task_command.py:467} INFO - Running <TaskInstance: data_processing.data_transform manual__2025-01-10T04:23:33.801988+00:00 [running]> on host bun
[2025-01-10T04:24:09.617+0000] {taskinstance.py:3132} INFO - Exporting env vars: AIRFLOW_CTX_DAG_OWNER='admin' AIRFLOW_CTX_DAG_ID='data_processing' AIRFLOW_CTX_TASK_ID='data_transform' AIRFLOW_CTX_EXECUTION_DATE='2025-01-10T04:23:33.801988+00:00' AIRFLOW_CTX_TRY_NUMBER='1' AIRFLOW_CTX_DAG_RUN_ID='manual__2025-01-10T04:23:33.801988+00:00'
[2025-01-10T04:24:09.619+0000] {logging_mixin.py:190} INFO - Task instance is in running state
[2025-01-10T04:24:09.619+0000] {logging_mixin.py:190} INFO -  Previous state of the Task instance: queued
[2025-01-10T04:24:09.619+0000] {logging_mixin.py:190} INFO - Current task name:data_transform state:running start_date:2025-01-10 04:24:09.504274+00:00
[2025-01-10T04:24:09.619+0000] {logging_mixin.py:190} INFO - Dag name:data_processing and current dag run status:running
[2025-01-10T04:24:09.619+0000] {taskinstance.py:731} INFO - ::endgroup::
[2025-01-10T04:24:09.674+0000] {docker.py:345} INFO - Starting docker container from image adzuna_data_transform:v2
[2025-01-10T04:24:11.112+0000] {docker.py:69} INFO - 25/01/10 04:24:11 WARN NativeCodeLoader: Unable to load native-hadoop library for your platform... using builtin-java classes where applicable
[2025-01-10T04:24:11.209+0000] {docker.py:69} INFO - Setting default log level to "WARN".
[2025-01-10T04:24:11.210+0000] {docker.py:69} INFO - To adjust logging level use sc.setLogLevel(newLevel). For SparkR, use setLogLevel(newLevel).
[2025-01-10T04:24:12.917+0000] {docker.py:69} INFO - Traceback (most recent call last):
[2025-01-10T04:24:12.919+0000] {docker.py:69} INFO -   File "/adzuna/script/adzuna_data_transformation.py", line 15, in <module>
[2025-01-10T04:24:12.920+0000] {docker.py:69} INFO -     df = spark.read.csv(f'data/Adzuna_{CURRENT_DATE}.csv', header=True)
[2025-01-10T04:24:12.920+0000] {docker.py:69} INFO -          ^^^^^^^^^^^^^^^^^^^^^^^^^^^^^^^^^^^^^^^^^^^^^^^^^^^^^^^^^^^^^^
[2025-01-10T04:24:12.920+0000] {docker.py:69} INFO -   File "/usr/local/lib/python3.12/site-packages/pyspark/sql/readwriter.py", line 740, in csv
[2025-01-10T04:24:12.921+0000] {docker.py:69} INFO -     return self._df(self._jreader.csv(self._spark._sc._jvm.PythonUtils.toSeq(path)))
[2025-01-10T04:24:12.921+0000] {docker.py:69} INFO -                     ^^^^^^^^^^^^^^^^^^^^^^^^^^^^^^^^^^^^^^^^^^^^^^^^^^^^^^^^^^^^^^^
[2025-01-10T04:24:12.921+0000] {docker.py:69} INFO -   File "/usr/local/lib/python3.12/site-packages/py4j/java_gateway.py", line 1322, in __call__
[2025-01-10T04:24:12.922+0000] {docker.py:69} INFO -     return_value = get_return_value(
[2025-01-10T04:24:12.922+0000] {docker.py:69} INFO -                    ^^^^^^^^^^^^^^^^^
[2025-01-10T04:24:12.922+0000] {docker.py:69} INFO -   File "/usr/local/lib/python3.12/site-packages/pyspark/errors/exceptions/captured.py", line 185, in deco
[2025-01-10T04:24:12.922+0000] {docker.py:69} INFO -     raise converted from None
[2025-01-10T04:24:12.925+0000] {docker.py:69} INFO - pyspark.errors.exceptions.captured.AnalysisException: [PATH_NOT_FOUND] Path does not exist: file:/adzuna/data/Adzuna_2025-01-10.csv.
[2025-01-10T04:24:13.077+0000] {taskinstance.py:3311} ERROR - Task failed with exception
Traceback (most recent call last):
  File "/home/adm1n/job_market/.venv/lib/python3.12/site-packages/airflow/models/taskinstance.py", line 767, in _execute_task
    result = _execute_callable(context=context, **execute_callable_kwargs)
             ^^^^^^^^^^^^^^^^^^^^^^^^^^^^^^^^^^^^^^^^^^^^^^^^^^^^^^^^^^^^^
  File "/home/adm1n/job_market/.venv/lib/python3.12/site-packages/airflow/models/taskinstance.py", line 733, in _execute_callable
    return ExecutionCallableRunner(
           ^^^^^^^^^^^^^^^^^^^^^^^^
  File "/home/adm1n/job_market/.venv/lib/python3.12/site-packages/airflow/utils/operator_helpers.py", line 252, in run
    return self.func(*args, **kwargs)
           ^^^^^^^^^^^^^^^^^^^^^^^^^^
  File "/home/adm1n/job_market/.venv/lib/python3.12/site-packages/airflow/models/baseoperator.py", line 422, in wrapper
    return func(self, *args, **kwargs)
           ^^^^^^^^^^^^^^^^^^^^^^^^^^^
  File "/home/adm1n/job_market/.venv/lib/python3.12/site-packages/airflow/providers/docker/operators/docker.py", line 485, in execute
    return self._run_image()
           ^^^^^^^^^^^^^^^^^
  File "/home/adm1n/job_market/.venv/lib/python3.12/site-packages/airflow/providers/docker/operators/docker.py", line 350, in _run_image
    return self._run_image_with_mounts([*self.mounts, tmp_mount], add_tmp_variable=True)
           ^^^^^^^^^^^^^^^^^^^^^^^^^^^^^^^^^^^^^^^^^^^^^^^^^^^^^^^^^^^^^^^^^^^^^^^^^^^^^
  File "/home/adm1n/job_market/.venv/lib/python3.12/site-packages/airflow/providers/docker/operators/docker.py", line 419, in _run_image_with_mounts
    raise DockerContainerFailedException(f"Docker container failed: {result!r}", logs=log_lines)
airflow.providers.docker.exceptions.DockerContainerFailedException: Docker container failed: {'StatusCode': 1}
[2025-01-10T04:24:13.083+0000] {logging_mixin.py:190} INFO - Task instance in failure state
[2025-01-10T04:24:13.083+0000] {logging_mixin.py:190} INFO - Task start:2025-01-10 04:24:09.504274+00:00 end:2025-01-10 04:24:13.081944+00:00 duration:3.57767
[2025-01-10T04:24:13.083+0000] {logging_mixin.py:190} INFO - Task:<Task(DockerOperator): data_transform> dag:<DAG: data_processing> dagrun:<DagRun data_processing @ 2025-01-10 04:23:33.801988+00:00: manual__2025-01-10T04:23:33.801988+00:00, state:running, queued_at: 2025-01-10 04:23:33.821417+00:00. externally triggered: True>
[2025-01-10T04:24:13.083+0000] {logging_mixin.py:190} INFO - Failure caused by Docker container failed: {'StatusCode': 1}
[2025-01-10T04:24:13.084+0000] {taskinstance.py:1225} INFO - Marking task as FAILED. dag_id=data_processing, task_id=data_transform, run_id=manual__2025-01-10T04:23:33.801988+00:00, execution_date=20250110T042333, start_date=20250110T042409, end_date=20250110T042413
[2025-01-10T04:24:13.093+0000] {taskinstance.py:340} INFO - ::group::Post task execution logs
[2025-01-10T04:24:13.094+0000] {standard_task_runner.py:124} ERROR - Failed to execute job 47 for task data_transform (Docker container failed: {'StatusCode': 1}; 23659)
Traceback (most recent call last):
  File "/home/adm1n/job_market/.venv/lib/python3.12/site-packages/airflow/task/task_runner/standard_task_runner.py", line 117, in _start_by_fork
    ret = args.func(args, dag=self.dag)
          ^^^^^^^^^^^^^^^^^^^^^^^^^^^^^
  File "/home/adm1n/job_market/.venv/lib/python3.12/site-packages/airflow/cli/cli_config.py", line 49, in command
    return func(*args, **kwargs)
           ^^^^^^^^^^^^^^^^^^^^^
  File "/home/adm1n/job_market/.venv/lib/python3.12/site-packages/airflow/utils/cli.py", line 116, in wrapper
    return f(*args, **kwargs)
           ^^^^^^^^^^^^^^^^^^
  File "/home/adm1n/job_market/.venv/lib/python3.12/site-packages/airflow/cli/commands/task_command.py", line 483, in task_run
    task_return_code = _run_task_by_selected_method(args, _dag, ti)
                       ^^^^^^^^^^^^^^^^^^^^^^^^^^^^^^^^^^^^^^^^^^^^
  File "/home/adm1n/job_market/.venv/lib/python3.12/site-packages/airflow/cli/commands/task_command.py", line 256, in _run_task_by_selected_method
    return _run_raw_task(args, ti)
           ^^^^^^^^^^^^^^^^^^^^^^^
  File "/home/adm1n/job_market/.venv/lib/python3.12/site-packages/airflow/cli/commands/task_command.py", line 341, in _run_raw_task
    return ti._run_raw_task(
           ^^^^^^^^^^^^^^^^^
  File "/home/adm1n/job_market/.venv/lib/python3.12/site-packages/airflow/utils/session.py", line 97, in wrapper
    return func(*args, session=session, **kwargs)
           ^^^^^^^^^^^^^^^^^^^^^^^^^^^^^^^^^^^^^^
  File "/home/adm1n/job_market/.venv/lib/python3.12/site-packages/airflow/models/taskinstance.py", line 3005, in _run_raw_task
    return _run_raw_task(
           ^^^^^^^^^^^^^^
  File "/home/adm1n/job_market/.venv/lib/python3.12/site-packages/airflow/models/taskinstance.py", line 273, in _run_raw_task
    TaskInstance._execute_task_with_callbacks(
  File "/home/adm1n/job_market/.venv/lib/python3.12/site-packages/airflow/models/taskinstance.py", line 3159, in _execute_task_with_callbacks
    result = self._execute_task(context, task_orig)
             ^^^^^^^^^^^^^^^^^^^^^^^^^^^^^^^^^^^^^^
  File "/home/adm1n/job_market/.venv/lib/python3.12/site-packages/airflow/models/taskinstance.py", line 3183, in _execute_task
    return _execute_task(self, context, task_orig)
           ^^^^^^^^^^^^^^^^^^^^^^^^^^^^^^^^^^^^^^^
  File "/home/adm1n/job_market/.venv/lib/python3.12/site-packages/airflow/models/taskinstance.py", line 767, in _execute_task
    result = _execute_callable(context=context, **execute_callable_kwargs)
             ^^^^^^^^^^^^^^^^^^^^^^^^^^^^^^^^^^^^^^^^^^^^^^^^^^^^^^^^^^^^^
  File "/home/adm1n/job_market/.venv/lib/python3.12/site-packages/airflow/models/taskinstance.py", line 733, in _execute_callable
    return ExecutionCallableRunner(
           ^^^^^^^^^^^^^^^^^^^^^^^^
  File "/home/adm1n/job_market/.venv/lib/python3.12/site-packages/airflow/utils/operator_helpers.py", line 252, in run
    return self.func(*args, **kwargs)
           ^^^^^^^^^^^^^^^^^^^^^^^^^^
  File "/home/adm1n/job_market/.venv/lib/python3.12/site-packages/airflow/models/baseoperator.py", line 422, in wrapper
    return func(self, *args, **kwargs)
           ^^^^^^^^^^^^^^^^^^^^^^^^^^^
  File "/home/adm1n/job_market/.venv/lib/python3.12/site-packages/airflow/providers/docker/operators/docker.py", line 485, in execute
    return self._run_image()
           ^^^^^^^^^^^^^^^^^
  File "/home/adm1n/job_market/.venv/lib/python3.12/site-packages/airflow/providers/docker/operators/docker.py", line 350, in _run_image
    return self._run_image_with_mounts([*self.mounts, tmp_mount], add_tmp_variable=True)
           ^^^^^^^^^^^^^^^^^^^^^^^^^^^^^^^^^^^^^^^^^^^^^^^^^^^^^^^^^^^^^^^^^^^^^^^^^^^^^
  File "/home/adm1n/job_market/.venv/lib/python3.12/site-packages/airflow/providers/docker/operators/docker.py", line 419, in _run_image_with_mounts
    raise DockerContainerFailedException(f"Docker container failed: {result!r}", logs=log_lines)
airflow.providers.docker.exceptions.DockerContainerFailedException: Docker container failed: {'StatusCode': 1}
[2025-01-10T04:24:13.145+0000] {local_task_job_runner.py:266} INFO - Task exited with return code 1
[2025-01-10T04:24:13.177+0000] {taskinstance.py:3895} INFO - 0 downstream tasks scheduled from follow-on schedule check
[2025-01-10T04:24:13.178+0000] {local_task_job_runner.py:245} INFO - ::endgroup::
