[2025-01-10T00:35:27.974+0000] {local_task_job_runner.py:123} INFO - ::group::Pre task execution logs
[2025-01-10T00:35:28.079+0000] {taskinstance.py:2613} INFO - Dependencies all met for dep_context=non-requeueable deps ti=<TaskInstance: data_processing.data_transform manual__2025-01-10T00:32:28.595354+00:00 [queued]>
[2025-01-10T00:35:28.096+0000] {taskinstance.py:2613} INFO - Dependencies all met for dep_context=requeueable deps ti=<TaskInstance: data_processing.data_transform manual__2025-01-10T00:32:28.595354+00:00 [queued]>
[2025-01-10T00:35:28.096+0000] {taskinstance.py:2866} INFO - Starting attempt 1 of 1
[2025-01-10T00:35:28.183+0000] {taskinstance.py:2889} INFO - Executing <Task(DockerOperator): data_transform> on 2025-01-10 00:32:28.595354+00:00
[2025-01-10T00:35:28.207+0000] {standard_task_runner.py:72} INFO - Started process 47351 to run task
[2025-01-10T00:35:28.213+0000] {standard_task_runner.py:104} INFO - Running: ['airflow', 'tasks', 'run', 'data_processing', 'data_transform', 'manual__2025-01-10T00:32:28.595354+00:00', '--job-id', '26', '--raw', '--subdir', 'DAGS_FOLDER/job_market_pipeline.py', '--cfg-path', '/tmp/tmpuc7jham8']
[2025-01-10T00:35:28.215+0000] {standard_task_runner.py:105} INFO - Job 26: Subtask data_transform
[2025-01-10T00:35:35.293+0000] {task_command.py:467} INFO - Running <TaskInstance: data_processing.data_transform manual__2025-01-10T00:32:28.595354+00:00 [running]> on host bun
[2025-01-10T00:36:06.524+0000] {job.py:229} INFO - Heartbeat recovered after 31.20 seconds
[2025-01-10T00:37:37.328+0000] {taskinstance.py:3132} INFO - Exporting env vars: AIRFLOW_CTX_DAG_OWNER='admin' AIRFLOW_CTX_DAG_ID='data_processing' AIRFLOW_CTX_TASK_ID='data_transform' AIRFLOW_CTX_EXECUTION_DATE='2025-01-10T00:32:28.595354+00:00' AIRFLOW_CTX_TRY_NUMBER='1' AIRFLOW_CTX_DAG_RUN_ID='manual__2025-01-10T00:32:28.595354+00:00'
[2025-01-10T00:37:37.376+0000] {logging_mixin.py:190} INFO - Task instance is in running state
[2025-01-10T00:37:37.377+0000] {logging_mixin.py:190} INFO -  Previous state of the Task instance: queued
[2025-01-10T00:37:37.380+0000] {logging_mixin.py:190} INFO - Current task name:data_transform state:running start_date:2025-01-10 00:35:28.084920+00:00
[2025-01-10T00:37:37.380+0000] {logging_mixin.py:190} INFO - Dag name:data_processing and current dag run status:running
[2025-01-10T00:37:37.381+0000] {taskinstance.py:731} INFO - ::endgroup::
[2025-01-10T00:37:37.394+0000] {job.py:229} INFO - Heartbeat recovered after 91.95 seconds
[2025-01-10T00:37:37.652+0000] {docker.py:345} INFO - Starting docker container from image adzuna_data_transform:v1
[2025-01-10T00:38:14.094+0000] {job.py:229} INFO - Heartbeat recovered after 23.80 seconds
[2025-01-10T00:39:02.664+0000] {job.py:229} INFO - Heartbeat recovered after 48.65 seconds
[2025-01-10T00:40:28.022+0000] {taskinstance.py:3311} ERROR - Task failed with exception
Traceback (most recent call last):
  File "/home/adm1n/job_market/.venv/lib/python3.12/site-packages/urllib3/connectionpool.py", line 536, in _make_request
    response = conn.getresponse()
               ^^^^^^^^^^^^^^^^^^
  File "/home/adm1n/job_market/.venv/lib/python3.12/site-packages/urllib3/connection.py", line 507, in getresponse
    httplib_response = super().getresponse()
                       ^^^^^^^^^^^^^^^^^^^^^
  File "/usr/lib/python3.12/http/client.py", line 1428, in getresponse
    response.begin()
  File "/usr/lib/python3.12/http/client.py", line 331, in begin
    version, status, reason = self._read_status()
                              ^^^^^^^^^^^^^^^^^^^
  File "/usr/lib/python3.12/http/client.py", line 292, in _read_status
    line = str(self.fp.readline(_MAXLINE + 1), "iso-8859-1")
               ^^^^^^^^^^^^^^^^^^^^^^^^^^^^^^
  File "/usr/lib/python3.12/socket.py", line 707, in readinto
    return self._sock.recv_into(b)
           ^^^^^^^^^^^^^^^^^^^^^^^
TimeoutError: timed out

The above exception was the direct cause of the following exception:

Traceback (most recent call last):
  File "/home/adm1n/job_market/.venv/lib/python3.12/site-packages/requests/adapters.py", line 667, in send
    resp = conn.urlopen(
           ^^^^^^^^^^^^^
  File "/home/adm1n/job_market/.venv/lib/python3.12/site-packages/urllib3/connectionpool.py", line 843, in urlopen
    retries = retries.increment(
              ^^^^^^^^^^^^^^^^^^
  File "/home/adm1n/job_market/.venv/lib/python3.12/site-packages/urllib3/util/retry.py", line 474, in increment
    raise reraise(type(error), error, _stacktrace)
          ^^^^^^^^^^^^^^^^^^^^^^^^^^^^^^^^^^^^^^^^
  File "/home/adm1n/job_market/.venv/lib/python3.12/site-packages/urllib3/util/util.py", line 39, in reraise
    raise value
  File "/home/adm1n/job_market/.venv/lib/python3.12/site-packages/urllib3/connectionpool.py", line 789, in urlopen
    response = self._make_request(
               ^^^^^^^^^^^^^^^^^^^
  File "/home/adm1n/job_market/.venv/lib/python3.12/site-packages/urllib3/connectionpool.py", line 538, in _make_request
    self._raise_timeout(err=e, url=url, timeout_value=read_timeout)
  File "/home/adm1n/job_market/.venv/lib/python3.12/site-packages/urllib3/connectionpool.py", line 369, in _raise_timeout
    raise ReadTimeoutError(
urllib3.exceptions.ReadTimeoutError: UnixHTTPConnectionPool(host='localhost', port=None): Read timed out. (read timeout=60)

During handling of the above exception, another exception occurred:

Traceback (most recent call last):
  File "/home/adm1n/job_market/.venv/lib/python3.12/site-packages/airflow/providers/docker/operators/docker.py", line 409, in _run_image_with_mounts
    self.cli.start(self.container["Id"])
  File "/home/adm1n/job_market/.venv/lib/python3.12/site-packages/docker/utils/decorators.py", line 19, in wrapped
    return f(self, resource_id, *args, **kwargs)
           ^^^^^^^^^^^^^^^^^^^^^^^^^^^^^^^^^^^^^
  File "/home/adm1n/job_market/.venv/lib/python3.12/site-packages/docker/api/container.py", line 1135, in start
    res = self._post(url)
          ^^^^^^^^^^^^^^^
  File "/home/adm1n/job_market/.venv/lib/python3.12/site-packages/docker/utils/decorators.py", line 44, in inner
    return f(self, *args, **kwargs)
           ^^^^^^^^^^^^^^^^^^^^^^^^
  File "/home/adm1n/job_market/.venv/lib/python3.12/site-packages/docker/api/client.py", line 242, in _post
    return self.post(url, **self._set_request_timeout(kwargs))
           ^^^^^^^^^^^^^^^^^^^^^^^^^^^^^^^^^^^^^^^^^^^^^^^^^^^
  File "/home/adm1n/job_market/.venv/lib/python3.12/site-packages/requests/sessions.py", line 637, in post
    return self.request("POST", url, data=data, json=json, **kwargs)
           ^^^^^^^^^^^^^^^^^^^^^^^^^^^^^^^^^^^^^^^^^^^^^^^^^^^^^^^^^
  File "/home/adm1n/job_market/.venv/lib/python3.12/site-packages/requests/sessions.py", line 589, in request
    resp = self.send(prep, **send_kwargs)
           ^^^^^^^^^^^^^^^^^^^^^^^^^^^^^^
  File "/home/adm1n/job_market/.venv/lib/python3.12/site-packages/requests/sessions.py", line 703, in send
    r = adapter.send(request, **kwargs)
        ^^^^^^^^^^^^^^^^^^^^^^^^^^^^^^^
  File "/home/adm1n/job_market/.venv/lib/python3.12/site-packages/requests/adapters.py", line 713, in send
    raise ReadTimeout(e, request=request)
requests.exceptions.ReadTimeout: UnixHTTPConnectionPool(host='localhost', port=None): Read timed out. (read timeout=60)

During handling of the above exception, another exception occurred:

Traceback (most recent call last):
  File "/home/adm1n/job_market/.venv/lib/python3.12/site-packages/urllib3/connectionpool.py", line 536, in _make_request
    response = conn.getresponse()
               ^^^^^^^^^^^^^^^^^^
  File "/home/adm1n/job_market/.venv/lib/python3.12/site-packages/urllib3/connection.py", line 507, in getresponse
    httplib_response = super().getresponse()
                       ^^^^^^^^^^^^^^^^^^^^^
  File "/usr/lib/python3.12/http/client.py", line 1428, in getresponse
    response.begin()
  File "/usr/lib/python3.12/http/client.py", line 331, in begin
    version, status, reason = self._read_status()
                              ^^^^^^^^^^^^^^^^^^^
  File "/usr/lib/python3.12/http/client.py", line 292, in _read_status
    line = str(self.fp.readline(_MAXLINE + 1), "iso-8859-1")
               ^^^^^^^^^^^^^^^^^^^^^^^^^^^^^^
  File "/usr/lib/python3.12/socket.py", line 707, in readinto
    return self._sock.recv_into(b)
           ^^^^^^^^^^^^^^^^^^^^^^^
TimeoutError: timed out

The above exception was the direct cause of the following exception:

Traceback (most recent call last):
  File "/home/adm1n/job_market/.venv/lib/python3.12/site-packages/requests/adapters.py", line 667, in send
    resp = conn.urlopen(
           ^^^^^^^^^^^^^
  File "/home/adm1n/job_market/.venv/lib/python3.12/site-packages/urllib3/connectionpool.py", line 843, in urlopen
    retries = retries.increment(
              ^^^^^^^^^^^^^^^^^^
  File "/home/adm1n/job_market/.venv/lib/python3.12/site-packages/urllib3/util/retry.py", line 474, in increment
    raise reraise(type(error), error, _stacktrace)
          ^^^^^^^^^^^^^^^^^^^^^^^^^^^^^^^^^^^^^^^^
  File "/home/adm1n/job_market/.venv/lib/python3.12/site-packages/urllib3/util/util.py", line 39, in reraise
    raise value
  File "/home/adm1n/job_market/.venv/lib/python3.12/site-packages/urllib3/connectionpool.py", line 789, in urlopen
    response = self._make_request(
               ^^^^^^^^^^^^^^^^^^^
  File "/home/adm1n/job_market/.venv/lib/python3.12/site-packages/urllib3/connectionpool.py", line 538, in _make_request
    self._raise_timeout(err=e, url=url, timeout_value=read_timeout)
  File "/home/adm1n/job_market/.venv/lib/python3.12/site-packages/urllib3/connectionpool.py", line 369, in _raise_timeout
    raise ReadTimeoutError(
urllib3.exceptions.ReadTimeoutError: UnixHTTPConnectionPool(host='localhost', port=None): Read timed out. (read timeout=60)

During handling of the above exception, another exception occurred:

Traceback (most recent call last):
  File "/home/adm1n/job_market/.venv/lib/python3.12/site-packages/airflow/models/taskinstance.py", line 767, in _execute_task
    result = _execute_callable(context=context, **execute_callable_kwargs)
             ^^^^^^^^^^^^^^^^^^^^^^^^^^^^^^^^^^^^^^^^^^^^^^^^^^^^^^^^^^^^^
  File "/home/adm1n/job_market/.venv/lib/python3.12/site-packages/airflow/models/taskinstance.py", line 733, in _execute_callable
    return ExecutionCallableRunner(
           ^^^^^^^^^^^^^^^^^^^^^^^^
  File "/home/adm1n/job_market/.venv/lib/python3.12/site-packages/airflow/utils/operator_helpers.py", line 252, in run
    return self.func(*args, **kwargs)
           ^^^^^^^^^^^^^^^^^^^^^^^^^^
  File "/home/adm1n/job_market/.venv/lib/python3.12/site-packages/airflow/models/baseoperator.py", line 422, in wrapper
    return func(self, *args, **kwargs)
           ^^^^^^^^^^^^^^^^^^^^^^^^^^^
  File "/home/adm1n/job_market/.venv/lib/python3.12/site-packages/airflow/providers/docker/operators/docker.py", line 485, in execute
    return self._run_image()
           ^^^^^^^^^^^^^^^^^
  File "/home/adm1n/job_market/.venv/lib/python3.12/site-packages/airflow/providers/docker/operators/docker.py", line 350, in _run_image
    return self._run_image_with_mounts([*self.mounts, tmp_mount], add_tmp_variable=True)
           ^^^^^^^^^^^^^^^^^^^^^^^^^^^^^^^^^^^^^^^^^^^^^^^^^^^^^^^^^^^^^^^^^^^^^^^^^^^^^
  File "/home/adm1n/job_market/.venv/lib/python3.12/site-packages/airflow/providers/docker/operators/docker.py", line 437, in _run_image_with_mounts
    self.cli.remove_container(self.container["Id"])
  File "/home/adm1n/job_market/.venv/lib/python3.12/site-packages/docker/utils/decorators.py", line 19, in wrapped
    return f(self, resource_id, *args, **kwargs)
           ^^^^^^^^^^^^^^^^^^^^^^^^^^^^^^^^^^^^^
  File "/home/adm1n/job_market/.venv/lib/python3.12/site-packages/docker/api/container.py", line 1034, in remove_container
    res = self._delete(
          ^^^^^^^^^^^^^
  File "/home/adm1n/job_market/.venv/lib/python3.12/site-packages/docker/utils/decorators.py", line 44, in inner
    return f(self, *args, **kwargs)
           ^^^^^^^^^^^^^^^^^^^^^^^^
  File "/home/adm1n/job_market/.venv/lib/python3.12/site-packages/docker/api/client.py", line 254, in _delete
    return self.delete(url, **self._set_request_timeout(kwargs))
           ^^^^^^^^^^^^^^^^^^^^^^^^^^^^^^^^^^^^^^^^^^^^^^^^^^^^^
  File "/home/adm1n/job_market/.venv/lib/python3.12/site-packages/requests/sessions.py", line 671, in delete
    return self.request("DELETE", url, **kwargs)
           ^^^^^^^^^^^^^^^^^^^^^^^^^^^^^^^^^^^^^
  File "/home/adm1n/job_market/.venv/lib/python3.12/site-packages/requests/sessions.py", line 589, in request
    resp = self.send(prep, **send_kwargs)
           ^^^^^^^^^^^^^^^^^^^^^^^^^^^^^^
  File "/home/adm1n/job_market/.venv/lib/python3.12/site-packages/requests/sessions.py", line 703, in send
    r = adapter.send(request, **kwargs)
        ^^^^^^^^^^^^^^^^^^^^^^^^^^^^^^^
  File "/home/adm1n/job_market/.venv/lib/python3.12/site-packages/requests/adapters.py", line 713, in send
    raise ReadTimeout(e, request=request)
requests.exceptions.ReadTimeout: UnixHTTPConnectionPool(host='localhost', port=None): Read timed out. (read timeout=60)
[2025-01-10T00:40:28.384+0000] {logging_mixin.py:190} INFO - Task instance in failure state
[2025-01-10T00:40:28.389+0000] {logging_mixin.py:190} INFO - Task start:2025-01-10 00:35:28.084920+00:00 end:2025-01-10 00:40:28.372235+00:00 duration:300.287315
[2025-01-10T00:40:28.395+0000] {logging_mixin.py:190} INFO - Task:<Task(DockerOperator): data_transform> dag:<DAG: data_processing> dagrun:<DagRun data_processing @ 2025-01-10 00:32:28.595354+00:00: manual__2025-01-10T00:32:28.595354+00:00, state:running, queued_at: 2025-01-10 00:32:28.605104+00:00. externally triggered: True>
[2025-01-10T00:40:28.405+0000] {logging_mixin.py:190} INFO - Failure caused by UnixHTTPConnectionPool(host='localhost', port=None): Read timed out. (read timeout=60)
[2025-01-10T00:40:28.411+0000] {taskinstance.py:1225} INFO - Marking task as FAILED. dag_id=data_processing, task_id=data_transform, run_id=manual__2025-01-10T00:32:28.595354+00:00, execution_date=20250110T003228, start_date=20250110T003528, end_date=20250110T004028
[2025-01-10T00:40:28.478+0000] {taskinstance.py:340} INFO - ::group::Post task execution logs
[2025-01-10T00:40:28.487+0000] {standard_task_runner.py:124} ERROR - Failed to execute job 26 for task data_transform (UnixHTTPConnectionPool(host='localhost', port=None): Read timed out. (read timeout=60); 47351)
Traceback (most recent call last):
  File "/home/adm1n/job_market/.venv/lib/python3.12/site-packages/urllib3/connectionpool.py", line 536, in _make_request
    response = conn.getresponse()
               ^^^^^^^^^^^^^^^^^^
  File "/home/adm1n/job_market/.venv/lib/python3.12/site-packages/urllib3/connection.py", line 507, in getresponse
    httplib_response = super().getresponse()
                       ^^^^^^^^^^^^^^^^^^^^^
  File "/usr/lib/python3.12/http/client.py", line 1428, in getresponse
    response.begin()
  File "/usr/lib/python3.12/http/client.py", line 331, in begin
    version, status, reason = self._read_status()
                              ^^^^^^^^^^^^^^^^^^^
  File "/usr/lib/python3.12/http/client.py", line 292, in _read_status
    line = str(self.fp.readline(_MAXLINE + 1), "iso-8859-1")
               ^^^^^^^^^^^^^^^^^^^^^^^^^^^^^^
  File "/usr/lib/python3.12/socket.py", line 707, in readinto
    return self._sock.recv_into(b)
           ^^^^^^^^^^^^^^^^^^^^^^^
TimeoutError: timed out

The above exception was the direct cause of the following exception:

Traceback (most recent call last):
  File "/home/adm1n/job_market/.venv/lib/python3.12/site-packages/requests/adapters.py", line 667, in send
    resp = conn.urlopen(
           ^^^^^^^^^^^^^
  File "/home/adm1n/job_market/.venv/lib/python3.12/site-packages/urllib3/connectionpool.py", line 843, in urlopen
    retries = retries.increment(
              ^^^^^^^^^^^^^^^^^^
  File "/home/adm1n/job_market/.venv/lib/python3.12/site-packages/urllib3/util/retry.py", line 474, in increment
    raise reraise(type(error), error, _stacktrace)
          ^^^^^^^^^^^^^^^^^^^^^^^^^^^^^^^^^^^^^^^^
  File "/home/adm1n/job_market/.venv/lib/python3.12/site-packages/urllib3/util/util.py", line 39, in reraise
    raise value
  File "/home/adm1n/job_market/.venv/lib/python3.12/site-packages/urllib3/connectionpool.py", line 789, in urlopen
    response = self._make_request(
               ^^^^^^^^^^^^^^^^^^^
  File "/home/adm1n/job_market/.venv/lib/python3.12/site-packages/urllib3/connectionpool.py", line 538, in _make_request
    self._raise_timeout(err=e, url=url, timeout_value=read_timeout)
  File "/home/adm1n/job_market/.venv/lib/python3.12/site-packages/urllib3/connectionpool.py", line 369, in _raise_timeout
    raise ReadTimeoutError(
urllib3.exceptions.ReadTimeoutError: UnixHTTPConnectionPool(host='localhost', port=None): Read timed out. (read timeout=60)

During handling of the above exception, another exception occurred:

Traceback (most recent call last):
  File "/home/adm1n/job_market/.venv/lib/python3.12/site-packages/airflow/providers/docker/operators/docker.py", line 409, in _run_image_with_mounts
    self.cli.start(self.container["Id"])
  File "/home/adm1n/job_market/.venv/lib/python3.12/site-packages/docker/utils/decorators.py", line 19, in wrapped
    return f(self, resource_id, *args, **kwargs)
           ^^^^^^^^^^^^^^^^^^^^^^^^^^^^^^^^^^^^^
  File "/home/adm1n/job_market/.venv/lib/python3.12/site-packages/docker/api/container.py", line 1135, in start
    res = self._post(url)
          ^^^^^^^^^^^^^^^
  File "/home/adm1n/job_market/.venv/lib/python3.12/site-packages/docker/utils/decorators.py", line 44, in inner
    return f(self, *args, **kwargs)
           ^^^^^^^^^^^^^^^^^^^^^^^^
  File "/home/adm1n/job_market/.venv/lib/python3.12/site-packages/docker/api/client.py", line 242, in _post
    return self.post(url, **self._set_request_timeout(kwargs))
           ^^^^^^^^^^^^^^^^^^^^^^^^^^^^^^^^^^^^^^^^^^^^^^^^^^^
  File "/home/adm1n/job_market/.venv/lib/python3.12/site-packages/requests/sessions.py", line 637, in post
    return self.request("POST", url, data=data, json=json, **kwargs)
           ^^^^^^^^^^^^^^^^^^^^^^^^^^^^^^^^^^^^^^^^^^^^^^^^^^^^^^^^^
  File "/home/adm1n/job_market/.venv/lib/python3.12/site-packages/requests/sessions.py", line 589, in request
    resp = self.send(prep, **send_kwargs)
           ^^^^^^^^^^^^^^^^^^^^^^^^^^^^^^
  File "/home/adm1n/job_market/.venv/lib/python3.12/site-packages/requests/sessions.py", line 703, in send
    r = adapter.send(request, **kwargs)
        ^^^^^^^^^^^^^^^^^^^^^^^^^^^^^^^
  File "/home/adm1n/job_market/.venv/lib/python3.12/site-packages/requests/adapters.py", line 713, in send
    raise ReadTimeout(e, request=request)
requests.exceptions.ReadTimeout: UnixHTTPConnectionPool(host='localhost', port=None): Read timed out. (read timeout=60)

During handling of the above exception, another exception occurred:

Traceback (most recent call last):
  File "/home/adm1n/job_market/.venv/lib/python3.12/site-packages/urllib3/connectionpool.py", line 536, in _make_request
    response = conn.getresponse()
               ^^^^^^^^^^^^^^^^^^
  File "/home/adm1n/job_market/.venv/lib/python3.12/site-packages/urllib3/connection.py", line 507, in getresponse
    httplib_response = super().getresponse()
                       ^^^^^^^^^^^^^^^^^^^^^
  File "/usr/lib/python3.12/http/client.py", line 1428, in getresponse
    response.begin()
  File "/usr/lib/python3.12/http/client.py", line 331, in begin
    version, status, reason = self._read_status()
                              ^^^^^^^^^^^^^^^^^^^
  File "/usr/lib/python3.12/http/client.py", line 292, in _read_status
    line = str(self.fp.readline(_MAXLINE + 1), "iso-8859-1")
               ^^^^^^^^^^^^^^^^^^^^^^^^^^^^^^
  File "/usr/lib/python3.12/socket.py", line 707, in readinto
    return self._sock.recv_into(b)
           ^^^^^^^^^^^^^^^^^^^^^^^
TimeoutError: timed out

The above exception was the direct cause of the following exception:

Traceback (most recent call last):
  File "/home/adm1n/job_market/.venv/lib/python3.12/site-packages/requests/adapters.py", line 667, in send
    resp = conn.urlopen(
           ^^^^^^^^^^^^^
  File "/home/adm1n/job_market/.venv/lib/python3.12/site-packages/urllib3/connectionpool.py", line 843, in urlopen
    retries = retries.increment(
              ^^^^^^^^^^^^^^^^^^
  File "/home/adm1n/job_market/.venv/lib/python3.12/site-packages/urllib3/util/retry.py", line 474, in increment
    raise reraise(type(error), error, _stacktrace)
          ^^^^^^^^^^^^^^^^^^^^^^^^^^^^^^^^^^^^^^^^
  File "/home/adm1n/job_market/.venv/lib/python3.12/site-packages/urllib3/util/util.py", line 39, in reraise
    raise value
  File "/home/adm1n/job_market/.venv/lib/python3.12/site-packages/urllib3/connectionpool.py", line 789, in urlopen
    response = self._make_request(
               ^^^^^^^^^^^^^^^^^^^
  File "/home/adm1n/job_market/.venv/lib/python3.12/site-packages/urllib3/connectionpool.py", line 538, in _make_request
    self._raise_timeout(err=e, url=url, timeout_value=read_timeout)
  File "/home/adm1n/job_market/.venv/lib/python3.12/site-packages/urllib3/connectionpool.py", line 369, in _raise_timeout
    raise ReadTimeoutError(
urllib3.exceptions.ReadTimeoutError: UnixHTTPConnectionPool(host='localhost', port=None): Read timed out. (read timeout=60)

During handling of the above exception, another exception occurred:

Traceback (most recent call last):
  File "/home/adm1n/job_market/.venv/lib/python3.12/site-packages/airflow/task/task_runner/standard_task_runner.py", line 117, in _start_by_fork
    ret = args.func(args, dag=self.dag)
          ^^^^^^^^^^^^^^^^^^^^^^^^^^^^^
  File "/home/adm1n/job_market/.venv/lib/python3.12/site-packages/airflow/cli/cli_config.py", line 49, in command
    return func(*args, **kwargs)
           ^^^^^^^^^^^^^^^^^^^^^
  File "/home/adm1n/job_market/.venv/lib/python3.12/site-packages/airflow/utils/cli.py", line 116, in wrapper
    return f(*args, **kwargs)
           ^^^^^^^^^^^^^^^^^^
  File "/home/adm1n/job_market/.venv/lib/python3.12/site-packages/airflow/cli/commands/task_command.py", line 483, in task_run
    task_return_code = _run_task_by_selected_method(args, _dag, ti)
                       ^^^^^^^^^^^^^^^^^^^^^^^^^^^^^^^^^^^^^^^^^^^^
  File "/home/adm1n/job_market/.venv/lib/python3.12/site-packages/airflow/cli/commands/task_command.py", line 256, in _run_task_by_selected_method
    return _run_raw_task(args, ti)
           ^^^^^^^^^^^^^^^^^^^^^^^
  File "/home/adm1n/job_market/.venv/lib/python3.12/site-packages/airflow/cli/commands/task_command.py", line 341, in _run_raw_task
    return ti._run_raw_task(
           ^^^^^^^^^^^^^^^^^
  File "/home/adm1n/job_market/.venv/lib/python3.12/site-packages/airflow/utils/session.py", line 97, in wrapper
    return func(*args, session=session, **kwargs)
           ^^^^^^^^^^^^^^^^^^^^^^^^^^^^^^^^^^^^^^
  File "/home/adm1n/job_market/.venv/lib/python3.12/site-packages/airflow/models/taskinstance.py", line 3005, in _run_raw_task
    return _run_raw_task(
           ^^^^^^^^^^^^^^
  File "/home/adm1n/job_market/.venv/lib/python3.12/site-packages/airflow/models/taskinstance.py", line 273, in _run_raw_task
    TaskInstance._execute_task_with_callbacks(
  File "/home/adm1n/job_market/.venv/lib/python3.12/site-packages/airflow/models/taskinstance.py", line 3159, in _execute_task_with_callbacks
    result = self._execute_task(context, task_orig)
             ^^^^^^^^^^^^^^^^^^^^^^^^^^^^^^^^^^^^^^
  File "/home/adm1n/job_market/.venv/lib/python3.12/site-packages/airflow/models/taskinstance.py", line 3183, in _execute_task
    return _execute_task(self, context, task_orig)
           ^^^^^^^^^^^^^^^^^^^^^^^^^^^^^^^^^^^^^^^
  File "/home/adm1n/job_market/.venv/lib/python3.12/site-packages/airflow/models/taskinstance.py", line 767, in _execute_task
    result = _execute_callable(context=context, **execute_callable_kwargs)
             ^^^^^^^^^^^^^^^^^^^^^^^^^^^^^^^^^^^^^^^^^^^^^^^^^^^^^^^^^^^^^
  File "/home/adm1n/job_market/.venv/lib/python3.12/site-packages/airflow/models/taskinstance.py", line 733, in _execute_callable
    return ExecutionCallableRunner(
           ^^^^^^^^^^^^^^^^^^^^^^^^
  File "/home/adm1n/job_market/.venv/lib/python3.12/site-packages/airflow/utils/operator_helpers.py", line 252, in run
    return self.func(*args, **kwargs)
           ^^^^^^^^^^^^^^^^^^^^^^^^^^
  File "/home/adm1n/job_market/.venv/lib/python3.12/site-packages/airflow/models/baseoperator.py", line 422, in wrapper
    return func(self, *args, **kwargs)
           ^^^^^^^^^^^^^^^^^^^^^^^^^^^
  File "/home/adm1n/job_market/.venv/lib/python3.12/site-packages/airflow/providers/docker/operators/docker.py", line 485, in execute
    return self._run_image()
           ^^^^^^^^^^^^^^^^^
  File "/home/adm1n/job_market/.venv/lib/python3.12/site-packages/airflow/providers/docker/operators/docker.py", line 350, in _run_image
    return self._run_image_with_mounts([*self.mounts, tmp_mount], add_tmp_variable=True)
           ^^^^^^^^^^^^^^^^^^^^^^^^^^^^^^^^^^^^^^^^^^^^^^^^^^^^^^^^^^^^^^^^^^^^^^^^^^^^^
  File "/home/adm1n/job_market/.venv/lib/python3.12/site-packages/airflow/providers/docker/operators/docker.py", line 437, in _run_image_with_mounts
    self.cli.remove_container(self.container["Id"])
  File "/home/adm1n/job_market/.venv/lib/python3.12/site-packages/docker/utils/decorators.py", line 19, in wrapped
    return f(self, resource_id, *args, **kwargs)
           ^^^^^^^^^^^^^^^^^^^^^^^^^^^^^^^^^^^^^
  File "/home/adm1n/job_market/.venv/lib/python3.12/site-packages/docker/api/container.py", line 1034, in remove_container
    res = self._delete(
          ^^^^^^^^^^^^^
  File "/home/adm1n/job_market/.venv/lib/python3.12/site-packages/docker/utils/decorators.py", line 44, in inner
    return f(self, *args, **kwargs)
           ^^^^^^^^^^^^^^^^^^^^^^^^
  File "/home/adm1n/job_market/.venv/lib/python3.12/site-packages/docker/api/client.py", line 254, in _delete
    return self.delete(url, **self._set_request_timeout(kwargs))
           ^^^^^^^^^^^^^^^^^^^^^^^^^^^^^^^^^^^^^^^^^^^^^^^^^^^^^
  File "/home/adm1n/job_market/.venv/lib/python3.12/site-packages/requests/sessions.py", line 671, in delete
    return self.request("DELETE", url, **kwargs)
           ^^^^^^^^^^^^^^^^^^^^^^^^^^^^^^^^^^^^^
  File "/home/adm1n/job_market/.venv/lib/python3.12/site-packages/requests/sessions.py", line 589, in request
    resp = self.send(prep, **send_kwargs)
           ^^^^^^^^^^^^^^^^^^^^^^^^^^^^^^
  File "/home/adm1n/job_market/.venv/lib/python3.12/site-packages/requests/sessions.py", line 703, in send
    r = adapter.send(request, **kwargs)
        ^^^^^^^^^^^^^^^^^^^^^^^^^^^^^^^
  File "/home/adm1n/job_market/.venv/lib/python3.12/site-packages/requests/adapters.py", line 713, in send
    raise ReadTimeout(e, request=request)
requests.exceptions.ReadTimeout: UnixHTTPConnectionPool(host='localhost', port=None): Read timed out. (read timeout=60)
