[2025-01-10T00:48:12.863+0000] {local_task_job_runner.py:123} INFO - ::group::Pre task execution logs
[2025-01-10T00:48:13.048+0000] {taskinstance.py:2613} INFO - Dependencies all met for dep_context=non-requeueable deps ti=<TaskInstance: data_processing.data_transform manual__2025-01-10T00:48:03.061755+00:00 [queued]>
[2025-01-10T00:48:13.051+0000] {taskinstance.py:2613} INFO - Dependencies all met for dep_context=requeueable deps ti=<TaskInstance: data_processing.data_transform manual__2025-01-10T00:48:03.061755+00:00 [queued]>
[2025-01-10T00:48:13.051+0000] {taskinstance.py:2866} INFO - Starting attempt 1 of 1
[2025-01-10T00:48:13.060+0000] {taskinstance.py:2889} INFO - Executing <Task(DockerOperator): data_transform> on 2025-01-10 00:48:03.061755+00:00
[2025-01-10T00:48:13.081+0000] {standard_task_runner.py:72} INFO - Started process 49224 to run task
[2025-01-10T00:48:13.087+0000] {standard_task_runner.py:104} INFO - Running: ['airflow', 'tasks', 'run', 'data_processing', 'data_transform', 'manual__2025-01-10T00:48:03.061755+00:00', '--job-id', '30', '--raw', '--subdir', 'DAGS_FOLDER/job_market_pipeline.py', '--cfg-path', '/tmp/tmpdfcpmxa0']
[2025-01-10T00:48:13.088+0000] {standard_task_runner.py:105} INFO - Job 30: Subtask data_transform
[2025-01-10T00:48:13.136+0000] {task_command.py:467} INFO - Running <TaskInstance: data_processing.data_transform manual__2025-01-10T00:48:03.061755+00:00 [running]> on host bun
[2025-01-10T00:48:13.200+0000] {taskinstance.py:3132} INFO - Exporting env vars: AIRFLOW_CTX_DAG_OWNER='admin' AIRFLOW_CTX_DAG_ID='data_processing' AIRFLOW_CTX_TASK_ID='data_transform' AIRFLOW_CTX_EXECUTION_DATE='2025-01-10T00:48:03.061755+00:00' AIRFLOW_CTX_TRY_NUMBER='1' AIRFLOW_CTX_DAG_RUN_ID='manual__2025-01-10T00:48:03.061755+00:00'
[2025-01-10T00:48:13.202+0000] {logging_mixin.py:190} INFO - Task instance is in running state
[2025-01-10T00:48:13.203+0000] {logging_mixin.py:190} INFO -  Previous state of the Task instance: queued
[2025-01-10T00:48:13.203+0000] {logging_mixin.py:190} INFO - Current task name:data_transform state:running start_date:2025-01-10 00:48:13.048346+00:00
[2025-01-10T00:48:13.203+0000] {logging_mixin.py:190} INFO - Dag name:data_processing and current dag run status:running
[2025-01-10T00:48:13.204+0000] {taskinstance.py:731} INFO - ::endgroup::
[2025-01-10T00:48:13.445+0000] {docker.py:345} INFO - Starting docker container from image adzuna_data_transform:v1
[2025-01-10T00:48:15.300+0000] {docker.py:69} INFO - python3: can't open file '/adzuna/adzuna_data_transformation.py': [Errno 2] No such file or directory
[2025-01-10T00:48:15.986+0000] {taskinstance.py:3311} ERROR - Task failed with exception
Traceback (most recent call last):
  File "/home/adm1n/job_market/.venv/lib/python3.12/site-packages/airflow/models/taskinstance.py", line 767, in _execute_task
    result = _execute_callable(context=context, **execute_callable_kwargs)
             ^^^^^^^^^^^^^^^^^^^^^^^^^^^^^^^^^^^^^^^^^^^^^^^^^^^^^^^^^^^^^
  File "/home/adm1n/job_market/.venv/lib/python3.12/site-packages/airflow/models/taskinstance.py", line 733, in _execute_callable
    return ExecutionCallableRunner(
           ^^^^^^^^^^^^^^^^^^^^^^^^
  File "/home/adm1n/job_market/.venv/lib/python3.12/site-packages/airflow/utils/operator_helpers.py", line 252, in run
    return self.func(*args, **kwargs)
           ^^^^^^^^^^^^^^^^^^^^^^^^^^
  File "/home/adm1n/job_market/.venv/lib/python3.12/site-packages/airflow/models/baseoperator.py", line 422, in wrapper
    return func(self, *args, **kwargs)
           ^^^^^^^^^^^^^^^^^^^^^^^^^^^
  File "/home/adm1n/job_market/.venv/lib/python3.12/site-packages/airflow/providers/docker/operators/docker.py", line 485, in execute
    return self._run_image()
           ^^^^^^^^^^^^^^^^^
  File "/home/adm1n/job_market/.venv/lib/python3.12/site-packages/airflow/providers/docker/operators/docker.py", line 350, in _run_image
    return self._run_image_with_mounts([*self.mounts, tmp_mount], add_tmp_variable=True)
           ^^^^^^^^^^^^^^^^^^^^^^^^^^^^^^^^^^^^^^^^^^^^^^^^^^^^^^^^^^^^^^^^^^^^^^^^^^^^^
  File "/home/adm1n/job_market/.venv/lib/python3.12/site-packages/airflow/providers/docker/operators/docker.py", line 419, in _run_image_with_mounts
    raise DockerContainerFailedException(f"Docker container failed: {result!r}", logs=log_lines)
airflow.providers.docker.exceptions.DockerContainerFailedException: Docker container failed: {'StatusCode': 2}
[2025-01-10T00:48:16.006+0000] {logging_mixin.py:190} INFO - Task instance in failure state
[2025-01-10T00:48:16.007+0000] {logging_mixin.py:190} INFO - Task start:2025-01-10 00:48:13.048346+00:00 end:2025-01-10 00:48:16.004697+00:00 duration:2.956351
[2025-01-10T00:48:16.008+0000] {logging_mixin.py:190} INFO - Task:<Task(DockerOperator): data_transform> dag:<DAG: data_processing> dagrun:<DagRun data_processing @ 2025-01-10 00:48:03.061755+00:00: manual__2025-01-10T00:48:03.061755+00:00, state:running, queued_at: 2025-01-10 00:48:03.083533+00:00. externally triggered: True>
[2025-01-10T00:48:16.009+0000] {logging_mixin.py:190} INFO - Failure caused by Docker container failed: {'StatusCode': 2}
[2025-01-10T00:48:16.010+0000] {taskinstance.py:1225} INFO - Marking task as FAILED. dag_id=data_processing, task_id=data_transform, run_id=manual__2025-01-10T00:48:03.061755+00:00, execution_date=20250110T004803, start_date=20250110T004813, end_date=20250110T004816
[2025-01-10T00:48:16.030+0000] {taskinstance.py:340} INFO - ::group::Post task execution logs
[2025-01-10T00:48:16.031+0000] {standard_task_runner.py:124} ERROR - Failed to execute job 30 for task data_transform (Docker container failed: {'StatusCode': 2}; 49224)
Traceback (most recent call last):
  File "/home/adm1n/job_market/.venv/lib/python3.12/site-packages/airflow/task/task_runner/standard_task_runner.py", line 117, in _start_by_fork
    ret = args.func(args, dag=self.dag)
          ^^^^^^^^^^^^^^^^^^^^^^^^^^^^^
  File "/home/adm1n/job_market/.venv/lib/python3.12/site-packages/airflow/cli/cli_config.py", line 49, in command
    return func(*args, **kwargs)
           ^^^^^^^^^^^^^^^^^^^^^
  File "/home/adm1n/job_market/.venv/lib/python3.12/site-packages/airflow/utils/cli.py", line 116, in wrapper
    return f(*args, **kwargs)
           ^^^^^^^^^^^^^^^^^^
  File "/home/adm1n/job_market/.venv/lib/python3.12/site-packages/airflow/cli/commands/task_command.py", line 483, in task_run
    task_return_code = _run_task_by_selected_method(args, _dag, ti)
                       ^^^^^^^^^^^^^^^^^^^^^^^^^^^^^^^^^^^^^^^^^^^^
  File "/home/adm1n/job_market/.venv/lib/python3.12/site-packages/airflow/cli/commands/task_command.py", line 256, in _run_task_by_selected_method
    return _run_raw_task(args, ti)
           ^^^^^^^^^^^^^^^^^^^^^^^
  File "/home/adm1n/job_market/.venv/lib/python3.12/site-packages/airflow/cli/commands/task_command.py", line 341, in _run_raw_task
    return ti._run_raw_task(
           ^^^^^^^^^^^^^^^^^
  File "/home/adm1n/job_market/.venv/lib/python3.12/site-packages/airflow/utils/session.py", line 97, in wrapper
    return func(*args, session=session, **kwargs)
           ^^^^^^^^^^^^^^^^^^^^^^^^^^^^^^^^^^^^^^
  File "/home/adm1n/job_market/.venv/lib/python3.12/site-packages/airflow/models/taskinstance.py", line 3005, in _run_raw_task
    return _run_raw_task(
           ^^^^^^^^^^^^^^
  File "/home/adm1n/job_market/.venv/lib/python3.12/site-packages/airflow/models/taskinstance.py", line 273, in _run_raw_task
    TaskInstance._execute_task_with_callbacks(
  File "/home/adm1n/job_market/.venv/lib/python3.12/site-packages/airflow/models/taskinstance.py", line 3159, in _execute_task_with_callbacks
    result = self._execute_task(context, task_orig)
             ^^^^^^^^^^^^^^^^^^^^^^^^^^^^^^^^^^^^^^
  File "/home/adm1n/job_market/.venv/lib/python3.12/site-packages/airflow/models/taskinstance.py", line 3183, in _execute_task
    return _execute_task(self, context, task_orig)
           ^^^^^^^^^^^^^^^^^^^^^^^^^^^^^^^^^^^^^^^
  File "/home/adm1n/job_market/.venv/lib/python3.12/site-packages/airflow/models/taskinstance.py", line 767, in _execute_task
    result = _execute_callable(context=context, **execute_callable_kwargs)
             ^^^^^^^^^^^^^^^^^^^^^^^^^^^^^^^^^^^^^^^^^^^^^^^^^^^^^^^^^^^^^
  File "/home/adm1n/job_market/.venv/lib/python3.12/site-packages/airflow/models/taskinstance.py", line 733, in _execute_callable
    return ExecutionCallableRunner(
           ^^^^^^^^^^^^^^^^^^^^^^^^
  File "/home/adm1n/job_market/.venv/lib/python3.12/site-packages/airflow/utils/operator_helpers.py", line 252, in run
    return self.func(*args, **kwargs)
           ^^^^^^^^^^^^^^^^^^^^^^^^^^
  File "/home/adm1n/job_market/.venv/lib/python3.12/site-packages/airflow/models/baseoperator.py", line 422, in wrapper
    return func(self, *args, **kwargs)
           ^^^^^^^^^^^^^^^^^^^^^^^^^^^
  File "/home/adm1n/job_market/.venv/lib/python3.12/site-packages/airflow/providers/docker/operators/docker.py", line 485, in execute
    return self._run_image()
           ^^^^^^^^^^^^^^^^^
  File "/home/adm1n/job_market/.venv/lib/python3.12/site-packages/airflow/providers/docker/operators/docker.py", line 350, in _run_image
    return self._run_image_with_mounts([*self.mounts, tmp_mount], add_tmp_variable=True)
           ^^^^^^^^^^^^^^^^^^^^^^^^^^^^^^^^^^^^^^^^^^^^^^^^^^^^^^^^^^^^^^^^^^^^^^^^^^^^^
  File "/home/adm1n/job_market/.venv/lib/python3.12/site-packages/airflow/providers/docker/operators/docker.py", line 419, in _run_image_with_mounts
    raise DockerContainerFailedException(f"Docker container failed: {result!r}", logs=log_lines)
airflow.providers.docker.exceptions.DockerContainerFailedException: Docker container failed: {'StatusCode': 2}
[2025-01-10T00:48:16.056+0000] {local_task_job_runner.py:266} INFO - Task exited with return code 1
[2025-01-10T00:48:16.083+0000] {taskinstance.py:3895} INFO - 0 downstream tasks scheduled from follow-on schedule check
[2025-01-10T00:48:16.083+0000] {local_task_job_runner.py:245} INFO - ::endgroup::
